package ai.corca.adcio_analytics.exception

internal const val UNKNOWN_EXCEPTION_MESSAGE = "Unknown error has occurred."
